Run failed: Traceback (most recent call last):
File "/var/sandbox/sandbox-python/tmp/dd076840_5f74_4cc5_badc_33ccf481baae.py", line 48, in
File "", line 18, in
File "", line 5, in main
File "/usr/local/lib/python3.10/site-packages/jinja2/environment.py", line 1195, in new
return env.from_string(source, template_class=cls)
File "/usr/local/lib/python3.10/site-packages/jinja2/environment.py", line 1092, in from_string
return cls.from_code(self, self.compile(source), gs, None)
File "/usr/local/lib/python3.10/site-packages/jinja2/environment.py", line 757, in compile
self.handle_exception(source=source_hint)
File "/usr/local/lib/python3.10/site-packages/jinja2/environment.py", line 925, in handle_exception
raise rewrite_traceback_stack(source=source)
File "", line 1, in template
jinja2.exceptions.TemplateSyntaxError: unexpected char '#' at 7
error: exit status 255